Workbook

Sheet Instructions
B2: Real Estate Professional - Time Tracking Log
B3: Contemporaneous record of hours for IRC Sec. 469(c)(7) substantiation
B5: HOW TO USE THIS WORKBOOK
B6: 1. Set up first | C6: On the Setup tab, list your properties/entities and adjust the activity categories. Everything else reads from those two lists.
B7: 2. Log as you go | C7: Enter one row per work session on the Time Log tab. Do it the same day - the value of this record is that it is contemporaneous.
B8: 3. Describe the work | C8: The Description column is what makes an entry defensible. "Showed 412 Elm to the Hartley family, 2 hrs incl. drive" survives review; "real estate work" does not.
B9: 4. Log non-RE work | C9: On Setup, enter monthly hours worked in any non-real-estate job or business. The >50% test needs this number.
B10: 5. Review the Dashboard | C10: It computes both statutory tests and per-property totals automatically. Send it to your CPA with the Time Log.
B12: THE TWO TESTS - IRC Sec. 469(c)(7)(B)
B13: The 750-hour test | C13: More than 750 hours of service during the tax year in real property trades or businesses in which you materially participate.
B14: The >50% test | C14: More than half of all personal services you performed in ALL trades or businesses during the year must be in real property trades or businesses.
B15: Both must be met | C15: Failing either one means no real estate professional status for the year.
B16: Filing jointly? | C16: One spouse must satisfy both tests alone. Hours cannot be combined for this purpose.
B17: Then, separately | C17: Material participation is tested per rental activity - commonly 500 hours each - unless you make the Sec. 469(c)(7)(A) election to aggregate. The Dashboard tracks each property against 500 hours.
B19: WHAT DOES NOT COUNT
B20: Investor activities | C20: Reviewing financial statements, compiling analyses for your own use, and non-managerial monitoring do NOT count - Reg. Sec. 1.469-5T(f)(2)(ii) - unless you are involved in day-to-day management or operations.
B21: Education | C21: Courses, seminars and licensing hours are generally not treated as participation.
B22: Commuting | C22: Home-to-office travel is not participation. Travel between properties is contested; it is flagged as such in the category list so your CPA can decide.
B24: CELL LEGEND
B25: Blue text | C25: You type here. All inputs are blue.
B26: Yellow fill | C26: Key input that drives the calculations - do not leave blank.
B27: Black text | C27: Calculated. Do not overwrite.
B28: Green text | C28: Pulled from another tab. Do not overwrite.
B31: One workbook per tax year. Row 5 of the Time Log is a filled-in example - overwrite it with your first real entry.
B33: This workbook is a record-keeping tool, not tax advice. Category classifications reflect the general rules cited above; your CPA should confirm how they apply to your facts before anything here is used on a return.

Sheet Dashboard
A1: Dashboard - Real Estate Professional Status
A2: All figures calculated from the Time Log and Setup tabs.
A3: Tax year | B3: 2025
A5: SUMMARY OF HOURS
A6: Total hours logged | B6: =SUM('Time Log'!$E$5:$E$1004)
A7: Qualifying real property hours | B7: =SUMIF('Time Log'!$F$5:$F$1004,"Yes",'Time Log'!$E$5:$E$1004)
A8: Non-qualifying hours (investor, education, commuting) | B8: =SUMIF('Time Log'!$F$5:$F$1004,"No",'Time Log'!$E$5:$E$1004)
A9: Hours in non-real-estate work | B9: =SUM(Setup!$H$4:$H$15)
A10: Total personal service hours (all trades or businesses) | B10: =B7+B9
A12: STATUTORY TESTS - IRC Sec. 469(c)(7)(B)
A13: Test | B13: Actual | C13: Threshold | D13: Result
A14: More than 750 hours in real property trades or businesses | B14: =B7 | C14: 750 | D14: =IF(B14>C14,"MET","NOT MET")
A15: More than 50% of all personal services in real property | B15: =IFERROR(B7/B10,0) | C15: 0.5 | D15: =IF(B15>C15,"MET","NOT MET")
A16: OVERALL - both tests must be met | D16: =IF(AND(D14="MET",D15="MET"),"QUALIFIES","DOES NOT QUALIFY")
A18: Hours still needed to clear 750 | B18: =MAX(0,750-B7)
A20: MATERIAL PARTICIPATION BY PROPERTY (500-hour test)
A21: Property / Entity | B21: Hours | C21: Qualifying | D21: 500-hour test
A22: =IF(Setup!$A4="","",Setup!$A4) | B22: =IF($A22="","",SUMIFS('Time Log'!$E$5:$E$1004,'Time Log'!$B$5:$B$1004,$A22)) | C22: =IF($A22="","",SUMIFS('Time Log'!$E$5:$E$1004,'Time Log'!$B$5:$B$1004,$A22,'Time Log'!$F$5:$F$1004,"Yes")) | D22: =IF($A22="","",IF(C22>500,"Met","Below 500"))
A23: =IF(Setup!$A5="","",Setup!$A5) | B23: =IF($A23="","",SUMIFS('Time Log'!$E$5:$E$1004,'Time Log'!$B$5:$B$1004,$A23)) | C23: =IF($A23="","",SUMIFS('Time Log'!$E$5:$E$1004,'Time Log'!$B$5:$B$1004,$A23,'Time Log'!$F$5:$F$1004,"Yes")) | D23: =IF($A23="","",IF(C23>500,"Met","Below 500"))
A24: =IF(Setup!$A6="","",Setup!$A6) | B24: =IF($A24="","",SUMIFS('Time Log'!$E$5:$E$1004,'Time Log'!$B$5:$B$1004,$A24)) | C24: =IF($A24="","",SUMIFS('Time Log'!$E$5:$E$1004,'Time Log'!$B$5:$B$1004,$A24,'Time Log'!$F$5:$F$1004,"Yes")) | D24: =IF($A24="","",IF(C24>500,"Met","Below 500"))
A25: =IF(Setup!$A7="","",Setup!$A7) | B25: =IF($A25="","",SUMIFS('Time Log'!$E$5:$E$1004,'Time Log'!$B$5:$B$1004,$A25)) | C25: =IF($A25="","",SUMIFS('Time Log'!$E$5:$E$1004,'Time Log'!$B$5:$B$1004,$A25,'Time Log'!$F$5:$F$1004,"Yes")) | D25: =IF($A25="","",IF(C25>500,"Met","Below 500"))
A26: =IF(Setup!$A8="","",Setup!$A8) | B26: =IF($A26="","",SUMIFS('Time Log'!$E$5:$E$1004,'Time Log'!$B$5:$B$1004,$A26)) | C26: =IF($A26="","",SUMIFS('Time Log'!$E$5:$E$1004,'Time Log'!$B$5:$B$1004,$A26,'Time Log'!$F$5:$F$1004,"Yes")) | D26: =IF($A26="","",IF(C26>500,"Met","Below 500"))
A27: =IF(Setup!$A9="","",Setup!$A9) | B27: =IF($A27="","",SUMIFS('Time Log'!$E$5:$E$1004,'Time Log'!$B$5:$B$1004,$A27)) | C27: =IF($A27="","",SUMIFS('Time Log'!$E$5:$E$1004,'Time Log'!$B$5:$B$1004,$A27,'Time Log'!$F$5:$F$1004,"Yes")) | D27: =IF($A27="","",IF(C27>500,"Met","Below 500"))
A28: =IF(Setup!$A10="","",Setup!$A10) | B28: =IF($A28="","",SUMIFS('Time Log'!$E$5:$E$1004,'Time Log'!$B$5:$B$1004,$A28)) | C28: =IF($A28="","",SUMIFS('Time Log'!$E$5:$E$1004,'Time Log'!$B$5:$B$1004,$A28,'Time Log'!$F$5:$F$1004,"Yes")) | D28: =IF($A28="","",IF(C28>500,"Met","Below 500"))
A29: =IF(Setup!$A11="","",Setup!$A11) | B29: =IF($A29="","",SUMIFS('Time Log'!$E$5:$E$1004,'Time Log'!$B$5:$B$1004,$A29)) | C29: =IF($A29="","",SUMIFS('Time Log'!$E$5:$E$1004,'Time Log'!$B$5:$B$1004,$A29,'Time Log'!$F$5:$F$1004,"Yes")) | D29: =IF($A29="","",IF(C29>500,"Met","Below 500"))
A30: =IF(Setup!$A12="","",Setup!$A12) | B30: =IF($A30="","",SUMIFS('Time Log'!$E$5:$E$1004,'Time Log'!$B$5:$B$1004,$A30)) | C30: =IF($A30="","",SUMIFS('Time Log'!$E$5:$E$1004,'Time Log'!$B$5:$B$1004,$A30,'Time Log'!$F$5:$F$1004,"Yes")) | D30: =IF($A30="","",IF(C30>500,"Met","Below 500"))
A31: =IF(Setup!$A13="","",Setup!$A13) | B31: =IF($A31="","",SUMIFS('Time Log'!$E$5:$E$1004,'Time Log'!$B$5:$B$1004,$A31)) | C31: =IF($A31="","",SUMIFS('Time Log'!$E$5:$E$1004,'Time Log'!$B$5:$B$1004,$A31,'Time Log'!$F$5:$F$1004,"Yes")) | D31: =IF($A31="","",IF(C31>500,"Met","Below 500"))
A32: =IF(Setup!$A14="","",Setup!$A14) | B32: =IF($A32="","",SUMIFS('Time Log'!$E$5:$E$1004,'Time Log'!$B$5:$B$1004,$A32)) | C32: =IF($A32="","",SUMIFS('Time Log'!$E$5:$E$1004,'Time Log'!$B$5:$B$1004,$A32,'Time Log'!$F$5:$F$1004,"Yes")) | D32: =IF($A32="","",IF(C32>500,"Met","Below 500"))
A33: =IF(Setup!$A15="","",Setup!$A15) | B33: =IF($A33="","",SUMIFS('Time Log'!$E$5:$E$1004,'Time Log'!$B$5:$B$1004,$A33)) | C33: =IF($A33="","",SUMIFS('Time Log'!$E$5:$E$1004,'Time Log'!$B$5:$B$1004,$A33,'Time Log'!$F$5:$F$1004,"Yes")) | D33: =IF($A33="","",IF(C33>500,"Met","Below 500"))
... A51: =IF(Setup!$A33="","",Setup!$A33) | B51: =IF($A51="","",SUMIFS('Time Log'!$E$5:$E$1004,'Time Log'!$B$5:$B$1004,$A51)) | C51: =IF($A51="","",SUMIFS('Time Log'!$E$5:$E$1004,'Time Log'!$B$5:$B$1004,$A51,'Time Log'!$F$5:$F$1004,"Yes")) | D51: =IF($A51="","",IF(C51>500,"Met","Below 500"))
A52: Total | B52: =SUM(B22:B51) | C52: =SUM(C22:C51)
A53: Per-activity 500-hour test applies unless the Sec. 469(c)(7)(A) aggregation election is made. Ask your CPA which applies.
A55: HOURS BY ACTIVITY CATEGORY
A56: Activity Category | B56: Hours | C56: Counts? | D56: % of qualifying
A57: =IF(Setup!$C4="","",Setup!$C4) | B57: =IF($A57="","",SUMIFS('Time Log'!$E$5:$E$1004,'Time Log'!$C$5:$C$1004,$A57)) | C57: =IF(Setup!$C4="","",Setup!$D4) | D57: =IF($A57="","",IF($C57<>"Yes","",IFERROR(B57/B7,0)))
A58: =IF(Setup!$C5="","",Setup!$C5) | B58: =IF($A58="","",SUMIFS('Time Log'!$E$5:$E$1004,'Time Log'!$C$5:$C$1004,$A58)) | C58: =IF(Setup!$C5="","",Setup!$D5) | D58: =IF($A58="","",IF($C58<>"Yes","",IFERROR(B58/B7,0)))
A59: =IF(Setup!$C6="","",Setup!$C6) | B59: =IF($A59="","",SUMIFS('Time Log'!$E$5:$E$1004,'Time Log'!$C$5:$C$1004,$A59)) | C59: =IF(Setup!$C6="","",Setup!$D6) | D59: =IF($A59="","",IF($C59<>"Yes","",IFERROR(B59/B7,0)))
A60: =IF(Setup!$C7="","",Setup!$C7) | B60: =IF($A60="","",SUMIFS('Time Log'!$E$5:$E$1004,'Time Log'!$C$5:$C$1004,$A60)) | C60: =IF(Setup!$C7="","",Setup!$D7) | D60: =IF($A60="","",IF($C60<>"Yes","",IFERROR(B60/B7,0)))
A61: =IF(Setup!$C8="","",Setup!$C8) | B61: =IF($A61="","",SUMIFS('Time Log'!$E$5:$E$1004,'Time Log'!$C$5:$C$1004,$A61)) | C61: =IF(Setup!$C8="","",Setup!$D8) | D61: =IF($A61="","",IF($C61<>"Yes","",IFERROR(B61/B7,0)))
A62: =IF(Setup!$C9="","",Setup!$C9) | B62: =IF($A62="","",SUMIFS('Time Log'!$E$5:$E$1004,'Time Log'!$C$5:$C$1004,$A62)) | C62: =IF(Setup!$C9="","",Setup!$D9) | D62: =IF($A62="","",IF($C62<>"Yes","",IFERROR(B62/B7,0)))
...

Sheet Setup
A1: Setup - edit these lists
A2: The Time Log dropdowns and every Dashboard total read from here.
A3: Properties / Entities | C3: Activity Category | D3: Counts Toward REPS? | E3: Basis / Note | G3: Month | H3: Hours in NON-real-estate work
A4: Brokerage - General (no property) | C4: Property showings & client tours | D4: Yes | E4: Brokerage - real property trade or business | G4: January | H4: 0
A5: 123 Oak Street - Rental | C5: Listing presentations & pricing analysis | D5: Yes | E5: Brokerage | G5: February | H5: 0
A6: 456 Maple Ave - Rental | C6: Buyer / seller consultations | D6: Yes | E6: Brokerage | G6: March | H6: 0
C7: Offer preparation & contract negotiation | D7: Yes | E7: Brokerage | G7: April | H7: 0
C8: Transaction coordination & closing | D8: Yes | E8: Brokerage | G8: May | H8: 0
C9: Acquisition research & due diligence | D9: Yes | E9: Acquisition - operational, not investor review | G9: June | H9: 0
C10: Tenant screening & leasing | D10: Yes | E10: Rental / leasing | G10: July | H10: 0
C11: Rent collection & tenant communications | D11: Yes | E11: Operation / management | G11: August | H11: 0
C12: Property maintenance & repairs (self-performed) | D12: Yes | E12: Operation | G12: September | H12: 0
C13: Contractor sourcing, coordination & supervision | D13: Yes | E13: Management | G13: October | H13: 0
C14: Property inspections & walkthroughs | D14: Yes | E14: Operation | G14: November | H14: 0
C15: Renovation / construction management | D15: Yes | E15: Construction / redevelopment | G15: December | H15: 0
C16: Property marketing & advertising | D16: Yes | E16: Operation / brokerage | G16: Total | H16: =SUM(H4:H15)
C17: Day-to-day operational bookkeeping (invoices, payables) | D17: Yes | E17: Operational, not investor analysis
C18: Vendor & insurance management | D18: Yes | E18: Management | G18: W-2 job, other businesses - anything not real property.
C19: Municipal / permitting / compliance work | D19: Yes | E19: Operation
C20: Travel between properties (business purpose) | D20: Yes | E20: CONTESTED - see Instructions; confirm with CPA
C21: Reviewing financial statements / operating reports | D21: No | E21: Investor activity - Reg. 1.469-5T(f)(2)(ii)(A)
C22: Preparing personal financial summaries or analyses | D22: No | E22: Investor activity - Reg. 1.469-5T(f)(2)(ii)(B)
C23: Non-managerial monitoring of investments | D23: No | E23: Investor activity - Reg. 1.469-5T(f)(2)(ii)(C)
C24: Continuing education, licensing & seminars | D24: No | E24: Education generally not participation; confirm with CPA
C25: Commuting (home to office) | D25: No | E25: Commuting is not participation
C26: Personal tax preparation & planning | D26: No | E26: Not a real property trade or business
C27: Work in a non-real-estate trade or business | D27: No | E27: Counts against the >50% test - log in Setup

Sheet Time Log
A1: Time Log
A2: One row per work session. Enter the same day it happens. Hours in decimals: 15 min = 0.25, 90 min = 1.50.
A4: Date | B4: Property / Entity | C4: Activity Category | D4: Description of Work Performed | E4: Hours | F4: Counts Toward REPS? | G4: Mo#
A5: 2025-01-06 | B5: 123 Oak Street - Rental | C5: Tenant screening & leasing | D5: Screened three applicants for the upstairs unit: ran credit and background checks, called two prior landlords, sent lease to selected tenant. | E5: 2.75 | F5: =IF($C5="","",IFERROR(INDEX(Setup!$D$4:$D$28,MATCH($C5,Setup!$C$4:$C$28,0)),"CHECK")) | G5: =IF($A5="","",MONTH($A5)) | I5: <- EXAMPLE ROW - overwrite with your first real entry
F6: =IF($C6="","",IFERROR(INDEX(Setup!$D$4:$D$28,MATCH($C6,Setup!$C$4:$C$28,0)),"CHECK")) | G6: =IF($A6="","",MONTH($A6))
F7: =IF($C7="","",IFERROR(INDEX(Setup!$D$4:$D$28,MATCH($C7,Setup!$C$4:$C$28,0)),"CHECK")) | G7: =IF($A7="","",MONTH($A7))
F8: =IF($C8="","",IFERROR(INDEX(Setup!$D$4:$D$28,MATCH($C8,Setup!$C$4:$C$28,0)),"CHECK")) | G8: =IF($A8="","",MONTH($A8))
F9: =IF($C9="","",IFERROR(INDEX(Setup!$D$4:$D$28,MATCH($C9,Setup!$C$4:$C$28,0)),"CHECK")) | G9: =IF($A9="","",MONTH($A9))
F10: =IF($C10="","",IFERROR(INDEX(Setup!$D$4:$D$28,MATCH($C10,Setup!$C$4:$C$28,0)),"CHECK")) | G10: =IF($A10="","",MONTH($A10))
F11: =IF($C11="","",IFERROR(INDEX(Setup!$D$4:$D$28,MATCH($C11,Setup!$C$4:$C$28,0)),"CHECK")) | G11: =IF($A11="","",MONTH($A11))
F12: =IF($C12="","",IFERROR(INDEX(Setup!$D$4:$D$28,MATCH($C12,Setup!$C$4:$C$28,0)),"CHECK")) | G12: =IF($A12="","",MONTH($A12))
F13: =IF($C13="","",IFERROR(INDEX(Setup!$D$4:$D$28,MATCH($C13,Setup!$C$4:$C$28,0)),"CHECK")) | G13: =IF($A13="","",MONTH($A13))
F14: =IF($C14="","",IFERROR(INDEX(Setup!$D$4:$D$28,MATCH($C14,Setup!$C$4:$C$28,0)),"CHECK")) | G14: =IF($A14="","",MONTH($A14))
F15: =IF($C15="","",IFERROR(INDEX(Setup!$D$4:$D$28,MATCH($C15,Setup!$C$4:$C$28,0)),"CHECK")) | G15: =IF($A15="","",MONTH($A15))
F16: =IF($C16="","",IFERROR(INDEX(Setup!$D$4:$D$28,MATCH($C16,Setup!$C$4:$C$28,0)),"CHECK")) | G16: =IF($A16="","",MONTH($A16))
F17: =IF($C17="","",IFERROR(INDEX(Setup!$D$4:$D$28,MATCH($C17,Setup!$C$4:$C$28,0)),"CHECK")) | G17: =IF($A17="","",MONTH($A17))
... F1004: =IF($C1004="","",IFERROR(INDEX(Setup!$D$4:$D$28,MATCH($C1004,Setup!$C$4:$C$28,0)),"CHECK")) | G1004: =IF($A1004="","",MONTH($A1004))
